<?xml version="1.0"?>
<robot xmlns:xacro="http://www.ros.org/wiki/xacro">
  
  <xacro:macro name="thumb_v2" params="type ns sign position orientation">

    <!-- KNUCKLE -->
    <joint name="${ns}_${type}_abd_joint" type="revolute">
      <origin xyz="${position}" rpy="${orientation}"/>
      <parent link="${ns}_palm_link"/>
      <child link="${ns}_${type}_knuckle_link"/>
      <axis xyz="0 0 1" />
      <limit effort="30" velocity="1.0" lower="-0.785398" upper="0.785398" />
    </joint>
    
    <link name="${ns}_${type}_knuckle_link">
      <inertial>
        <origin xyz="0 0 0"/>
        <mass value="0.009"/>
        <inertia ixx="0.001" ixy="0" ixz="0" iyy="0.001" iyz="0" izz="0.001"/>
      </inertial>
      <visual>
	<geometry>
	  <mesh filename="package://softhands_description/meshes/softhands/v2.0/right/qbh_prox_thumb_ng.stl" scale="0.001 0.001 0.001"/> 
	</geometry>
	<material name="qbmove/default"/>
	<origin xyz="0 0 0" rpy="0 0 0"/>
      </visual>		
      <collision>
	<geometry>
	  <mesh filename="package://softhands_description/meshes/softhands/v2.0/right/qbh_prox_thumb_ng.stl" scale="0.001 0.001 0.001"/> 
	</geometry>
	<origin xyz="0 0 0" rpy="0 0 0"/>
      </collision>	      
    </link>
    <gazebo reference="${ns}_${type}_knuckle_link">
      <material>Gazebo/Grey</material>
      <selfCollide>true</selfCollide>
    </gazebo>
    
    <joint name="${ns}_${type}_inner_joint" type="revolute">
      <origin xyz="0.017 -0.00343074 0.00392231" rpy="1.6580634 0 0"/>
      <parent link="${ns}_${type}_knuckle_link"/>
      <child link="${ns}_${type}_proximal_link_fake"/>
      <axis xyz="0 0 1" />
      <limit effort="30" velocity="1.0" lower="-0.785398" upper="0.785398" />
    </joint>
    
    <link name="${ns}_${type}_proximal_link_fake">
      <inertial>
	<origin xyz="0 0 0" rpy="0 0 0"/>
	<mass value="1e-5"/>
	<inertia ixx="1e-8"  ixy="0"  	    ixz="0" 
				iyy="1e-8" 	    iyz="0" 
						    izz="1e-8" />
      </inertial>
    </link>
    
    <joint name="${ns}_${type}_inner_joint_mimic" type="revolute">
      <origin xyz="0.013 0 0" rpy="0 0 0"/>
      <parent link="${ns}_${type}_proximal_link_fake"/>
      <child link="${ns}_${type}_proximal_link"/>
      <axis xyz="0 0 1" />
      <limit effort="30" velocity="1.0" lower="-0.785398" upper="0.785398" />
    </joint>
    
    <link name="${ns}_${type}_proximal_link">
      <inertial>
        <origin xyz="0.005074337 0 0"/>
        <mass value="0.05"/>
        <inertia ixx="0.001" ixy="0" ixz="0" iyy="0.001" iyz="0" izz="0.001"/>
      </inertial>
      <visual>
	<geometry>
	  <mesh filename="package://softhands_description/meshes/softhands/v2.0/right/phalanx_std_ng.stl" scale="0.001 0.001 0.001"/> 
	</geometry>
	<material name="qbmove/default"/>
	<origin xyz="0 0 0" rpy="0 0 0"/>
      </visual>		
      <collision>
        <geometry>
          <mesh filename="package://softhands_description/meshes/softhands/v2.0/right/phalanx_std_ng.stl" scale="0.001 0.001 0.001"/> 
        </geometry>
        <origin xyz="0 0 0" rpy="0 0 0"/>
      </collision>      
    </link>
    <gazebo reference="${ns}_${type}_proximal_link">
      <material>Gazebo/Grey</material>
      <selfCollide>true</selfCollide>
    </gazebo>

    <joint name="${ns}_${type}_outer_joint" type="revolute">
      <origin xyz="0.009 0 0" rpy="0 0 0"/>
      <parent link="${ns}_${type}_proximal_link"/>
      <child link="${ns}_${type}_distal_link_fake"/>
      <limit effort="30" velocity="1.0" lower="-0.785398" upper="0.785398" />
      <axis xyz="0 0 1" />
    </joint>
    
    <link name="${ns}_${type}_distal_link_fake">
     <inertial>
	<origin xyz="0 0 0" rpy="0 0 0"/>
	<mass value="1e-5"/>
	<inertia ixx="1e-8"  ixy="0"  	    ixz="0" 
				iyy="1e-8" 	    iyz="0" 
						    izz="1e-8" />
      </inertial>
    </link>    
    
    <joint name="${ns}_${type}_outer_joint_mimic" type="revolute">
      <origin xyz="0.013 0 0" rpy="0 0 0"/>
      <parent link="${ns}_${type}_distal_link_fake"/>
      <child link="${ns}_${type}_distal_link"/>
      <limit effort="30" velocity="1.0" lower="-0.785398" upper="0.785398" />
      <axis xyz="0 0 1" />
    </joint>
    
    <link name="${ns}_${type}_distal_link">
      <inertial>
        <origin xyz="0.005074337 0 0"/>
        <mass value="0.05"/>
        <inertia ixx="0.001" ixy="0" ixz="0" iyy="0.001" iyz="0" izz="0.001"/>
      </inertial>
      <visual>
	<geometry>
	  <mesh filename="package://softhands_description/meshes/softhands/v2.0/right/qb_distal_ng.stl" scale="0.001 0.001 0.001"/> 
	</geometry>
	<material name="qbmove/default"/>
	<origin xyz="0 0 0" rpy="0 0 0"/>
      </visual>		
      <collision>
        <geometry>
          <mesh filename="package://softhands_description/meshes/softhands/v2.0/right/qb_distal_ng.stl" scale="0.001 0.001 0.001"/> 
        </geometry>
        <origin xyz="0 0 0" rpy="0 0 0"/>
      </collision>        
    </link>
    <gazebo reference="${ns}_${type}_distal_link">
      <material>Gazebo/Grey</material>
      <selfCollide>true</selfCollide>
    </gazebo>
    
    <gazebo>
      <plugin name="${type}_sh_abd_plugin" filename="libsofthands_plugin.so">
	<joint>${ns}_${type}_abd_joint</joint>  
	<namespace>${ns}</namespace>
	<stiffness>10</stiffness>
      </plugin>
    </gazebo>
    <gazebo>
      <plugin name="${type}_sh_inn_plugin" filename="libsofthands_plugin.so">
	<joint>${ns}_${type}_inner_joint</joint>  
	<namespace>${ns}</namespace>
	<stiffness>10</stiffness>
      </plugin>
    </gazebo>
    <gazebo>
      <plugin name="${type}_sh_out_plugin" filename="libsofthands_plugin.so">
	<joint>${ns}_${type}_outer_joint</joint>  
	<namespace>${ns}</namespace>
	<stiffness>10</stiffness>
      </plugin>
    </gazebo>
    </xacro:macro>
</robot>
    