<?xml version="1.0"?>

<robot xmlns:xacro="http://www.ros.org/wiki/xacro">
   
    <xacro:macro name="palm_little" params="name parent side ns mass *origin **inertia_origin *inertia ">


		<joint name="${ns}_${parent}_virtual_joint" type="revolute">
			<parent link="${ns}_${parent}_link"/>
			<child link="${ns}_${name}_link"/>
			<xacro:insert_block name="origin"/>
			<axis xyz="0 0 1" />
      		<limit effort="30" velocity="0.0" lower="0" upper="0.35" />
			<dynamics damping="$(arg damping)" friction="$(arg friction)"/>
		</joint>

	
		<link name="${ns}_${name}_link">
				<visual>
				<material name="grey" />
					<geometry>
					<mesh
						filename="package://softhands_description/meshes/v1_wide/${side}/palm_little.stl"
						scale="0.001 0.001 0.001" />
					</geometry>
				<origin xyz="0 0 0" rpy="0 0 0" />
				</visual>
				<inertial>
					<mass value="${mass}" />
					<xacro:insert_block name="inertia_origin"/>
					<xacro:insert_block name="inertia"/>
					</inertial>
				<collision>
					<geometry>
					<mesh
						filename="package://softhands_description/meshes/v1_wide/${side}/palm_little_collision.stl"
						scale="0.0009 0.0009 0.0009" />
					</geometry>
				<origin xyz="0 0 0" rpy="0 0 0" />
				</collision>
		</link>

		<gazebo reference="${ns}_${name}_link">
			<selfCollide>0</selfCollide>
			<material>Gazebo/Grey</material>
		</gazebo>


		        <!-- GAZEBO REF -->
		<gazebo reference="${ns}_${name}_virtual_joint">
		<implicitSpringDamper>true</implicitSpringDamper>
				<springStiffness>0.4</springStiffness>
				<springReference>0</springReference>
		</gazebo>

    </xacro:macro>
</robot>