<?xml version="1.0"?>

<robot xmlns:xacro="http://www.ros.org/wiki/xacro">
   
    <xacro:macro name="thumb_proximal" params="name parent side ns mass *origin **inertia_origin *inertia">
		


		<!-- Virtual joint from thumb knuckle to thumb proximal   -->
		<joint name="${ns}_${name}_joint" type="revolute">
			<axis xyz="0 0 1"/>
			<limit effort="30" velocity="0.0" lower="0" upper="0.785398" />
			<xacro:insert_block name="origin"/>
			<parent link="${ns}_${parent}_link"/>
			<child link="${ns}_${name}_virtual_link"/>
			<dynamics damping="$(arg virtual_damping)" friction="$(arg virtual_friction)"/>
		</joint>

	    <link name="${ns}_${name}_virtual_link">
		   <inertial>
				<origin rpy="0 0 0" xyz="0 0 0"/>
				<mass value="${mass}"/>
				<xacro:insert_block name="inertia"/>
		   </inertial>
	    </link>


		<!-- Thumb Proximal joint  -->
		<joint name="${ns}_${name}_virtual_joint" type="revolute">
			<parent link="${ns}_${name}_virtual_link"/>
			<child link="${ns}_${name}_link"/>
			<origin rpy="0 0 0"  xyz="9e-3 0 0 "/>
			<axis xyz="0 0 1" />
      		<limit effort="30" velocity="0.0" lower="0" upper="0.785398" />
			<dynamics damping="$(arg damping)" friction="$(arg friction)"/>
		</joint>

	
		<link name="${ns}_${name}_link">
				<visual>
				<material name="grey" />
					<geometry>
					<mesh
						filename="package://softhands_description/meshes/v1_wide/${side}/phalanx_medium_thumb.stl"
						scale="0.001 0.001 0.001" />
					</geometry>
				<origin xyz="0 0 0" rpy="0 0 0" />
				</visual>
				<inertial>
					<mass value="${mass}"/>
					<xacro:insert_block name="inertia"/>
					<xacro:insert_block name="inertia_origin"/>
				</inertial>
				<collision>
					<geometry>
					<mesh
						filename="package://softhands_description/meshes/v1_wide/${side}/phalanx_medium_thumb_collision.stl"
						scale="0.0009 0.0009 0.0009" />
					</geometry>
				<origin xyz="0 0 0" rpy="0 0 0" />
				</collision>
		</link>

		<gazebo reference="${ns}_${name}_link">
			<material>Gazebo/Grey</material>
			<selfCollide>$(arg selfCollide)</selfCollide>
		</gazebo>

				        <!-- GAZEBO REF -->
		<gazebo reference="${ns}_${name}_joint">
		<implicitSpringDamper>true</implicitSpringDamper>
				<springStiffness>0.4</springStiffness>
				<springReference>0</springReference>
		</gazebo>

				        <!-- GAZEBO REF -->
		<gazebo reference="${ns}_${name}_virtual_joint">
		<implicitSpringDamper>true</implicitSpringDamper>
				<springStiffness>0.4</springStiffness>
				<springReference>0</springReference>
		</gazebo>

    </xacro:macro>
</robot>