<sdf version='1.6'>
  <world name='default'>
    <light name='sun' type='directional'>
      <cast_shadows>1</cast_shadows>
      <pose frame=''>0 0 10 0 -0 0</pose>
      <diffuse>0.8 0.8 0.8 1</diffuse>
      <specular>0.2 0.2 0.2 1</specular>
      <attenuation>
        <range>1000</range>
        <constant>0.9</constant>
        <linear>0.01</linear>
        <quadratic>0.001</quadratic>
      </attenuation>
      <direction>-0.5 0.1 -0.9</direction>
    </light>
    <model name='ground_plane'>
      <static>1</static>
      <link name='link'>
        <collision name='collision'>
          <geometry>
            <plane>
              <normal>0 0 1</normal>
              <size>100 100</size>
            </plane>
          </geometry>
          <surface>
            <contact>
              <collide_bitmask>65535</collide_bitmask>
              <ode/>
            </contact>
            <friction>
              <ode>
                <mu>100</mu>
                <mu2>50</mu2>
              </ode>
              <torsional>
                <ode/>
              </torsional>
            </friction>
            <bounce/>
          </surface>
          <max_contacts>10</max_contacts>
        </collision>
        <visual name='visual'>
          <cast_shadows>0</cast_shadows>
          <geometry>
            <plane>
              <normal>0 0 1</normal>
              <size>100 100</size>
            </plane>
          </geometry>
          <material>
            <script>
              <uri>file://media/materials/scripts/gazebo.material</uri>
              <name>Gazebo/Grey</name>
            </script>
          </material>
        </visual>
        <self_collide>0</self_collide>
        <enable_wind>0</enable_wind>
        <kinematic>0</kinematic>
      </link>
    </model>
    <gravity>0 0 -9.8</gravity>
    <magnetic_field>6e-06 2.3e-05 -4.2e-05</magnetic_field>
    <atmosphere type='adiabatic'/>
    <physics name='default_physics' default='0' type='ode'>
      <max_step_size>0.001</max_step_size>
      <real_time_factor>1</real_time_factor>
      <real_time_update_rate>1000</real_time_update_rate>
    </physics>
    <scene>
      <ambient>0.4 0.4 0.4 1</ambient>
      <background>0.7 0.7 0.7 1</background>
      <shadows>1</shadows>
    </scene>
    <audio>
      <device>default</device>
    </audio>
    <wind/>
    <spherical_coordinates>
      <surface_model>EARTH_WGS84</surface_model>
      <latitude_deg>0</latitude_deg>
      <longitude_deg>0</longitude_deg>
      <elevation>0</elevation>
      <heading_deg>0</heading_deg>
    </spherical_coordinates>
    <model name='softhands_description'>
      <link name='object'>
        <pose frame=''>0.04 0.03 0.11 0 -0 0</pose>
        <inertial>
          <pose frame=''>0 0 0 0 -0 0</pose>
          <mass>1</mass>
          <inertia>
            <ixx>0.001</ixx>
            <ixy>0</ixy>
            <ixz>0</ixz>
            <iyy>0.001</iyy>
            <iyz>0</iyz>
            <izz>0.001</izz>
          </inertia>
        </inertial>
        <collision name='object_collision'>
          <pose frame=''>0 0 0 0 -0 0</pose>
          <geometry>
            <box>
              <size>0.04 0.04 0.04</size>
            </box>
          </geometry>
          <max_contacts>10</max_contacts>
          <surface>
            <contact>
              <ode/>
            </contact>
            <bounce/>
            <friction>
              <torsional>
                <ode/>
              </torsional>
              <ode/>
            </friction>
          </surface>
        </collision>
        <visual name='object_visual'>
          <pose frame=''>0 0 0 0 -0 0</pose>
          <geometry>
            <box>
              <size>0.04 0.04 0.04</size>
            </box>
          </geometry>
        </visual>
        <self_collide>0</self_collide>
        <enable_wind>0</enable_wind>
        <kinematic>0</kinematic>
      </link>
      <joint name='object_joint' type='fixed'>
        <child>object</child>
        <parent>world</parent>
      </joint>
      <link name='right_hand_palm_base'>
        <pose frame=''>0 0 0 0 -0 0</pose>
        <inertial>
          <pose frame=''>0.027653 0.006808 -0.004569 0 -0 0</pose>
          <mass>0.266</mass>
          <inertia>
            <ixx>0.001</ixx>
            <ixy>6.77626e-21</ixy>
            <ixz>-6.77626e-21</ixz>
            <iyy>0.001</iyy>
            <iyz>0</iyz>
            <izz>0.001</izz>
          </inertia>
        </inertial>
        <collision name='right_hand_palm_base_fixed_joint_lump__right_hand_palm_link_collision'>
          <pose frame=''>0 0 0 3.14159 -1.57079 -3e-06</pose>
          <geometry>
            <mesh>
              <scale>0.001 0.001 0.001</scale>
              <uri>/home/centropiaggio/riccardo_ws/src/lab_library_ros/softhands/softhands_description/meshes/softhands/v2.0/right/qbh_palm_ng.stl</uri>
            </mesh>
          </geometry>
          <surface>
            <contact>
              <ode/>
            </contact>
            <friction>
              <ode/>
              <torsional>
                <ode/>
              </torsional>
            </friction>
            <bounce/>
          </surface>
          <max_contacts>10</max_contacts>
        </collision>
        <visual name='right_hand_palm_base_fixed_joint_lump__right_hand_palm_link_visual'>
          <pose frame=''>0 0 0 3.14159 -1.57079 -3e-06</pose>
          <geometry>
            <mesh>
              <scale>0.001 0.001 0.001</scale>
              <uri>/home/centropiaggio/riccardo_ws/src/lab_library_ros/softhands/softhands_description/meshes/softhands/v2.0/right/qbh_palm_ng.stl</uri>
            </mesh>
          </geometry>
          <material>
            <script>
              <name>Gazebo/Grey</name>
              <uri>file://media/materials/scripts/gazebo.material</uri>
            </script>
          </material>
        </visual>
        <gravity>1</gravity>
        <velocity_decay/>
        <self_collide>1</self_collide>
        <enable_wind>0</enable_wind>
        <kinematic>0</kinematic>
      </link>
      <joint name='right_hand_base_joint' type='fixed'>
        <child>right_hand_palm_base</child>
        <parent>world</parent>
      </joint>
      <link name='right_hand_index_knuckle_link'>
        <pose frame=''>0.007582 0.0255 0.099006 1.56621 -1.39626 1.57531</pose>
        <inertial>
          <pose frame=''>0.001286 0 0.000425 0 -0 0</pose>
          <mass>0.009</mass>
          <inertia>
            <ixx>0.001</ixx>
            <ixy>0</ixy>
            <ixz>0</ixz>
            <iyy>0.001</iyy>
            <iyz>0</iyz>
            <izz>0.001</izz>
          </inertia>
        </inertial>
        <collision name='right_hand_index_knuckle_link_collision'>
          <pose frame=''>0 0 0 0 -0 0</pose>
          <geometry>
            <mesh>
              <scale>0.001 0.001 0.001</scale>
              <uri>/home/centropiaggio/riccardo_ws/src/lab_library_ros/softhands/softhands_description/meshes/softhands/v2.0/right/qbh_prossimal_std_r_ng.stl</uri>
            </mesh>
          </geometry>
          <surface>
            <contact>
              <ode/>
            </contact>
            <friction>
              <ode/>
              <torsional>
                <ode/>
              </torsional>
            </friction>
            <bounce/>
          </surface>
          <max_contacts>10</max_contacts>
        </collision>
        <visual name='right_hand_index_knuckle_link_visual'>
          <pose frame=''>0 0 0 0 -0 0</pose>
          <geometry>
            <mesh>
              <scale>0.001 0.001 0.001</scale>
              <uri>/home/centropiaggio/riccardo_ws/src/lab_library_ros/softhands/softhands_description/meshes/softhands/v2.0/right/qbh_prossimal_std_r_ng.stl</uri>
            </mesh>
          </geometry>
          <material>
            <script>
              <name>Gazebo/Grey</name>
              <uri>file://media/materials/scripts/gazebo.material</uri>
            </script>
          </material>
        </visual>
        <gravity>1</gravity>
        <velocity_decay/>
        <self_collide>1</self_collide>
        <enable_wind>0</enable_wind>
        <kinematic>0</kinematic>
      </link>
      <joint name='right_hand_index_knuckle_joint' type='revolute'>
        <child>right_hand_index_knuckle_link</child>
        <parent>right_hand_palm_base</parent>
        <axis>
          <xyz>1 -3e-06 0.000796</xyz>
          <limit>
            <lower>-0.785398</lower>
            <upper>1.57</upper>
            <effort>30</effort>
            <velocity>1</velocity>
          </limit>
          <dynamics>
            <damping>0.02</damping>
            <friction>0</friction>
            <spring_reference>0</spring_reference>
            <spring_stiffness>0</spring_stiffness>
          </dynamics>
          <use_parent_model_frame>1</use_parent_model_frame>
        </axis>
      </joint>
      <link name='right_hand_index_proximal_link'>
        <pose frame=''>0.007565 0.026899 0.120185 3.13701 -1.39626 1.57531</pose>
        <inertial>
          <pose frame=''>0.011574 0 0 0 -0 0</pose>
          <mass>0.005</mass>
          <inertia>
            <ixx>0.001</ixx>
            <ixy>0</ixy>
            <ixz>0</ixz>
            <iyy>0.001</iyy>
            <iyz>0</iyz>
            <izz>0.001</izz>
          </inertia>
        </inertial>
        <collision name='right_hand_index_proximal_link_collision'>
          <pose frame=''>0.0065 0 0 0 -0 0</pose>
          <geometry>
            <mesh>
              <scale>0.001 0.001 0.001</scale>
              <uri>/home/centropiaggio/riccardo_ws/src/lab_library_ros/softhands/softhands_description/meshes/softhands/v2.0/right/phalanx_std_ng.stl</uri>
            </mesh>
          </geometry>
          <surface>
            <contact>
              <ode/>
            </contact>
            <friction>
              <ode/>
              <torsional>
                <ode/>
              </torsional>
            </friction>
            <bounce/>
          </surface>
          <max_contacts>10</max_contacts>
        </collision>
        <visual name='right_hand_index_proximal_link_visual'>
          <pose frame=''>0.0065 0 0 0 -0 0</pose>
          <geometry>
            <mesh>
              <scale>0.001 0.001 0.001</scale>
              <uri>/home/centropiaggio/riccardo_ws/src/lab_library_ros/softhands/softhands_description/meshes/softhands/v2.0/right/phalanx_std_ng.stl</uri>
            </mesh>
          </geometry>
          <material>
            <script>
              <name>Gazebo/Grey</name>
              <uri>file://media/materials/scripts/gazebo.material</uri>
            </script>
          </material>
        </visual>
        <gravity>1</gravity>
        <velocity_decay/>
        <self_collide>1</self_collide>
        <enable_wind>0</enable_wind>
        <kinematic>0</kinematic>
      </link>
      <joint name='right_hand_index_proximal_joint' type='revolute'>
        <child>right_hand_index_proximal_link</child>
        <parent>right_hand_index_knuckle_link</parent>
        <axis>
          <xyz>0.000141 0.984808 -0.173648</xyz>
          <limit>
            <lower>-0.785398</lower>
            <upper>1.57</upper>
            <effort>30</effort>
            <velocity>1</velocity>
          </limit>
          <dynamics>
            <damping>0.02</damping>
            <friction>0</friction>
            <spring_reference>0</spring_reference>
            <spring_stiffness>0</spring_stiffness>
          </dynamics>
          <use_parent_model_frame>1</use_parent_model_frame>
        </axis>
      </joint>
      <link name='right_hand_index_middle_link'>
        <pose frame=''>0.007548 0.030719 0.141851 3.13701 -1.39626 1.57531</pose>
        <inertial>
          <pose frame=''>0.011574 0 0 0 -0 0</pose>
          <mass>0.005</mass>
          <inertia>
            <ixx>0.001</ixx>
            <ixy>0</ixy>
            <ixz>0</ixz>
            <iyy>0.001</iyy>
            <iyz>0</iyz>
            <izz>0.001</izz>
          </inertia>
        </inertial>
        <collision name='right_hand_index_middle_link_collision'>
          <pose frame=''>0.0065 0 0 0 -0 0</pose>
          <geometry>
            <mesh>
              <scale>0.001 0.001 0.001</scale>
              <uri>/home/centropiaggio/riccardo_ws/src/lab_library_ros/softhands/softhands_description/meshes/softhands/v2.0/right/phalanx_std_ng.stl</uri>
            </mesh>
          </geometry>
          <surface>
            <contact>
              <ode/>
            </contact>
            <friction>
              <ode/>
              <torsional>
                <ode/>
              </torsional>
            </friction>
            <bounce/>
          </surface>
          <max_contacts>10</max_contacts>
        </collision>
        <visual name='right_hand_index_middle_link_visual'>
          <pose frame=''>0.0065 0 0 0 -0 0</pose>
          <geometry>
            <mesh>
              <scale>0.001 0.001 0.001</scale>
              <uri>/home/centropiaggio/riccardo_ws/src/lab_library_ros/softhands/softhands_description/meshes/softhands/v2.0/right/phalanx_std_ng.stl</uri>
            </mesh>
          </geometry>
          <material>
            <script>
              <name>Gazebo/Grey</name>
              <uri>file://media/materials/scripts/gazebo.material</uri>
            </script>
          </material>
        </visual>
        <gravity>1</gravity>
        <velocity_decay/>
        <self_collide>1</self_collide>
        <enable_wind>0</enable_wind>
        <kinematic>0</kinematic>
      </link>
      <joint name='right_hand_index_middle_joint' type='revolute'>
        <child>right_hand_index_middle_link</child>
        <parent>right_hand_index_proximal_link</parent>
        <axis>
          <xyz>0.000141 0.984808 -0.173648</xyz>
          <limit>
            <lower>-0.785398</lower>
            <upper>1.57</upper>
            <effort>30</effort>
            <velocity>1</velocity>
          </limit>
          <dynamics>
            <damping>0.02</damping>
            <friction>0</friction>
            <spring_reference>0</spring_reference>
            <spring_stiffness>0</spring_stiffness>
          </dynamics>
          <use_parent_model_frame>1</use_parent_model_frame>
        </axis>
      </joint>
      <link name='right_hand_index_distal_link'>
        <pose frame=''>0.00753 0.034539 0.163516 3.13701 -1.39626 1.57531</pose>
        <inertial>
          <pose frame=''>0.011574 0 0 0 -0 0</pose>
          <mass>0.005</mass>
          <inertia>
            <ixx>0.001</ixx>
            <ixy>0</ixy>
            <ixz>0</ixz>
            <iyy>0.001</iyy>
            <iyz>0</iyz>
            <izz>0.001</izz>
          </inertia>
        </inertial>
        <collision name='right_hand_index_distal_link_collision'>
          <pose frame=''>0.0065 0 0 0 -0 0</pose>
          <geometry>
            <mesh>
              <scale>0.001 0.001 0.001</scale>
              <uri>/home/centropiaggio/riccardo_ws/src/lab_library_ros/softhands/softhands_description/meshes/softhands/v2.0/right/qb_distal_ng.stl</uri>
            </mesh>
          </geometry>
          <surface>
            <contact>
              <ode/>
            </contact>
            <friction>
              <ode/>
              <torsional>
                <ode/>
              </torsional>
            </friction>
            <bounce/>
          </surface>
          <max_contacts>10</max_contacts>
        </collision>
        <visual name='right_hand_index_distal_link_visual'>
          <pose frame=''>0.0065 0 0 0 -0 0</pose>
          <geometry>
            <mesh>
              <scale>0.001 0.001 0.001</scale>
              <uri>/home/centropiaggio/riccardo_ws/src/lab_library_ros/softhands/softhands_description/meshes/softhands/v2.0/right/qb_distal_ng.stl</uri>
            </mesh>
          </geometry>
          <material>
            <script>
              <name>Gazebo/Grey</name>
              <uri>file://media/materials/scripts/gazebo.material</uri>
            </script>
          </material>
        </visual>
        <gravity>1</gravity>
        <velocity_decay/>
        <self_collide>1</self_collide>
        <enable_wind>0</enable_wind>
        <kinematic>0</kinematic>
      </link>
      <joint name='right_hand_index_distal_joint' type='revolute'>
        <child>right_hand_index_distal_link</child>
        <parent>right_hand_index_middle_link</parent>
        <axis>
          <xyz>0.000141 0.984808 -0.173648</xyz>
          <limit>
            <lower>-0.785398</lower>
            <upper>1.57</upper>
            <effort>30</effort>
            <velocity>1</velocity>
          </limit>
          <dynamics>
            <damping>0.02</damping>
            <friction>0</friction>
            <spring_reference>0</spring_reference>
            <spring_stiffness>0</spring_stiffness>
          </dynamics>
          <use_parent_model_frame>1</use_parent_model_frame>
        </axis>
      </joint>
      <link name='right_hand_little_knuckle_link'>
        <pose frame=''>0.007586 -0.0257 0.094006 -1.56772 -1.309 -1.57377</pose>
        <inertial>
          <pose frame=''>0.001286 0 0.000425 0 -0 0</pose>
          <mass>0.009</mass>
          <inertia>
            <ixx>0.001</ixx>
            <ixy>0</ixy>
            <ixz>0</ixz>
            <iyy>0.001</iyy>
            <iyz>0</iyz>
            <izz>0.001</izz>
          </inertia>
        </inertial>
        <collision name='right_hand_little_knuckle_link_collision'>
          <pose frame=''>0 0 0 0 -0 0</pose>
          <geometry>
            <mesh>
              <scale>0.001 0.001 0.001</scale>
              <uri>/home/centropiaggio/riccardo_ws/src/lab_library_ros/softhands/softhands_description/meshes/softhands/v2.0/right/qbh_prossimal_std_l_ng.stl</uri>
            </mesh>
          </geometry>
          <surface>
            <contact>
              <ode/>
            </contact>
            <friction>
              <ode/>
              <torsional>
                <ode/>
              </torsional>
            </friction>
            <bounce/>
          </surface>
          <max_contacts>10</max_contacts>
        </collision>
        <visual name='right_hand_little_knuckle_link_visual'>
          <pose frame=''>0 0 0 0 -0 0</pose>
          <geometry>
            <mesh>
              <scale>0.001 0.001 0.001</scale>
              <uri>/home/centropiaggio/riccardo_ws/src/lab_library_ros/softhands/softhands_description/meshes/softhands/v2.0/right/qbh_prossimal_std_l_ng.stl</uri>
            </mesh>
          </geometry>
          <material>
            <script>
              <name>Gazebo/Grey</name>
              <uri>file://media/materials/scripts/gazebo.material</uri>
            </script>
          </material>
        </visual>
        <gravity>1</gravity>
        <velocity_decay/>
        <self_collide>1</self_collide>
        <enable_wind>0</enable_wind>
        <kinematic>0</kinematic>
      </link>
      <joint name='right_hand_little_knuckle_joint' type='revolute'>
        <child>right_hand_little_knuckle_link</child>
        <parent>right_hand_palm_base</parent>
        <axis>
          <xyz>1 -3e-06 0.000796</xyz>
          <limit>
            <lower>-0.785398</lower>
            <upper>1.57</upper>
            <effort>30</effort>
            <velocity>1</velocity>
          </limit>
          <dynamics>
            <damping>0.02</damping>
            <friction>0</friction>
            <spring_reference>0</spring_reference>
            <spring_stiffness>0</spring_stiffness>
          </dynamics>
          <use_parent_model_frame>1</use_parent_model_frame>
        </axis>
      </joint>
      <link name='right_hand_little_proximal_link'>
        <pose frame=''>0.007569 -0.02894 0.114982 0.003077 -1.309 -1.57377</pose>
        <inertial>
          <pose frame=''>0.011574 0 0 0 -0 0</pose>
          <mass>0.005</mass>
          <inertia>
            <ixx>0.001</ixx>
            <ixy>0</ixy>
            <ixz>0</ixz>
            <iyy>0.001</iyy>
            <iyz>0</iyz>
            <izz>0.001</izz>
          </inertia>
        </inertial>
        <collision name='right_hand_little_proximal_link_collision'>
          <pose frame=''>0.0065 0 0 0 -0 0</pose>
          <geometry>
            <mesh>
              <scale>0.001 0.001 0.001</scale>
              <uri>/home/centropiaggio/riccardo_ws/src/lab_library_ros/softhands/softhands_description/meshes/softhands/v2.0/right/phalanx_std_ng.stl</uri>
            </mesh>
          </geometry>
          <surface>
            <contact>
              <ode/>
            </contact>
            <friction>
              <ode/>
              <torsional>
                <ode/>
              </torsional>
            </friction>
            <bounce/>
          </surface>
          <max_contacts>10</max_contacts>
        </collision>
        <visual name='right_hand_little_proximal_link_visual'>
          <pose frame=''>0.0065 0 0 0 -0 0</pose>
          <geometry>
            <mesh>
              <scale>0.001 0.001 0.001</scale>
              <uri>/home/centropiaggio/riccardo_ws/src/lab_library_ros/softhands/softhands_description/meshes/softhands/v2.0/right/phalanx_std_ng.stl</uri>
            </mesh>
          </geometry>
          <material>
            <script>
              <name>Gazebo/Grey</name>
              <uri>file://media/materials/scripts/gazebo.material</uri>
            </script>
          </material>
        </visual>
        <gravity>1</gravity>
        <velocity_decay/>
        <self_collide>1</self_collide>
        <enable_wind>0</enable_wind>
        <kinematic>0</kinematic>
      </link>
      <joint name='right_hand_little_proximal_joint' type='revolute'>
        <child>right_hand_little_proximal_link</child>
        <parent>right_hand_little_knuckle_link</parent>
        <axis>
          <xyz>-0.000204 0.965926 0.258819</xyz>
          <limit>
            <lower>-0.785398</lower>
            <upper>1.57</upper>
            <effort>30</effort>
            <velocity>1</velocity>
          </limit>
          <dynamics>
            <damping>0.02</damping>
            <friction>0</friction>
            <spring_reference>0</spring_reference>
            <spring_stiffness>0</spring_stiffness>
          </dynamics>
          <use_parent_model_frame>1</use_parent_model_frame>
        </axis>
      </joint>
      <link name='right_hand_little_middle_link'>
        <pose frame=''>0.007552 -0.034634 0.136233 0.003077 -1.309 -1.57377</pose>
        <inertial>
          <pose frame=''>0.011574 0 0 0 -0 0</pose>
          <mass>0.005</mass>
          <inertia>
            <ixx>0.001</ixx>
            <ixy>0</ixy>
            <ixz>0</ixz>
            <iyy>0.001</iyy>
            <iyz>0</iyz>
            <izz>0.001</izz>
          </inertia>
        </inertial>
        <collision name='right_hand_little_middle_link_collision'>
          <pose frame=''>0.0065 0 0 0 -0 0</pose>
          <geometry>
            <mesh>
              <scale>0.001 0.001 0.001</scale>
              <uri>/home/centropiaggio/riccardo_ws/src/lab_library_ros/softhands/softhands_description/meshes/softhands/v2.0/right/phalanx_std_ng.stl</uri>
            </mesh>
          </geometry>
          <surface>
            <contact>
              <ode/>
            </contact>
            <friction>
              <ode/>
              <torsional>
                <ode/>
              </torsional>
            </friction>
            <bounce/>
          </surface>
          <max_contacts>10</max_contacts>
        </collision>
        <visual name='right_hand_little_middle_link_visual'>
          <pose frame=''>0.0065 0 0 0 -0 0</pose>
          <geometry>
            <mesh>
              <scale>0.001 0.001 0.001</scale>
              <uri>/home/centropiaggio/riccardo_ws/src/lab_library_ros/softhands/softhands_description/meshes/softhands/v2.0/right/phalanx_std_ng.stl</uri>
            </mesh>
          </geometry>
          <material>
            <script>
              <name>Gazebo/Grey</name>
              <uri>file://media/materials/scripts/gazebo.material</uri>
            </script>
          </material>
        </visual>
        <gravity>1</gravity>
        <velocity_decay/>
        <self_collide>1</self_collide>
        <enable_wind>0</enable_wind>
        <kinematic>0</kinematic>
      </link>
      <joint name='right_hand_little_middle_joint' type='revolute'>
        <child>right_hand_little_middle_link</child>
        <parent>right_hand_little_proximal_link</parent>
        <axis>
          <xyz>-0.000204 0.965926 0.258819</xyz>
          <limit>
            <lower>-0.785398</lower>
            <upper>1.57</upper>
            <effort>30</effort>
            <velocity>1</velocity>
          </limit>
          <dynamics>
            <damping>0.02</damping>
            <friction>0</friction>
            <spring_reference>0</spring_reference>
            <spring_stiffness>0</spring_stiffness>
          </dynamics>
          <use_parent_model_frame>1</use_parent_model_frame>
        </axis>
      </joint>
      <link name='right_hand_little_distal_link'>
        <pose frame=''>0.007535 -0.040328 0.157483 0.003077 -1.309 -1.57377</pose>
        <inertial>
          <pose frame=''>0.011574 0 0 0 -0 0</pose>
          <mass>0.005</mass>
          <inertia>
            <ixx>0.001</ixx>
            <ixy>0</ixy>
            <ixz>0</ixz>
            <iyy>0.001</iyy>
            <iyz>0</iyz>
            <izz>0.001</izz>
          </inertia>
        </inertial>
        <collision name='right_hand_little_distal_link_collision'>
          <pose frame=''>0.0065 0 0 0 -0 0</pose>
          <geometry>
            <mesh>
              <scale>0.001 0.001 0.001</scale>
              <uri>/home/centropiaggio/riccardo_ws/src/lab_library_ros/softhands/softhands_description/meshes/softhands/v2.0/right/qb_distal_ng.stl</uri>
            </mesh>
          </geometry>
          <surface>
            <contact>
              <ode/>
            </contact>
            <friction>
              <ode/>
              <torsional>
                <ode/>
              </torsional>
            </friction>
            <bounce/>
          </surface>
          <max_contacts>10</max_contacts>
        </collision>
        <visual name='right_hand_little_distal_link_visual'>
          <pose frame=''>0.0065 0 0 0 -0 0</pose>
          <geometry>
            <mesh>
              <scale>0.001 0.001 0.001</scale>
              <uri>/home/centropiaggio/riccardo_ws/src/lab_library_ros/softhands/softhands_description/meshes/softhands/v2.0/right/qb_distal_ng.stl</uri>
            </mesh>
          </geometry>
          <material>
            <script>
              <name>Gazebo/Grey</name>
              <uri>file://media/materials/scripts/gazebo.material</uri>
            </script>
          </material>
        </visual>
        <gravity>1</gravity>
        <velocity_decay/>
        <self_collide>1</self_collide>
        <enable_wind>0</enable_wind>
        <kinematic>0</kinematic>
      </link>
      <joint name='right_hand_little_distal_joint' type='revolute'>
        <child>right_hand_little_distal_link</child>
        <parent>right_hand_little_middle_link</parent>
        <axis>
          <xyz>-0.000204 0.965926 0.258819</xyz>
          <limit>
            <lower>-0.785398</lower>
            <upper>1.57</upper>
            <effort>30</effort>
            <velocity>1</velocity>
          </limit>
          <dynamics>
            <damping>0.02</damping>
            <friction>0</friction>
            <spring_reference>0</spring_reference>
            <spring_stiffness>0</spring_stiffness>
          </dynamics>
          <use_parent_model_frame>1</use_parent_model_frame>
        </axis>
      </joint>
      <link name='right_hand_middle_knuckle_link'>
        <pose frame=''>0.007578 0.0075 0.104006 0 -1.57 3.14159</pose>
        <inertial>
          <pose frame=''>0.001286 0 0.000425 0 -0 0</pose>
          <mass>0.009</mass>
          <inertia>
            <ixx>0.001</ixx>
            <ixy>0</ixy>
            <ixz>0</ixz>
            <iyy>0.001</iyy>
            <iyz>0</iyz>
            <izz>0.001</izz>
          </inertia>
        </inertial>
        <collision name='right_hand_middle_knuckle_link_collision'>
          <pose frame=''>0 0 0 0 -0 0</pose>
          <geometry>
            <mesh>
              <scale>0.001 0.001 0.001</scale>
              <uri>/home/centropiaggio/riccardo_ws/src/lab_library_ros/softhands/softhands_description/meshes/softhands/v2.0/right/qbh_prossimal_std_m_ng.stl</uri>
            </mesh>
          </geometry>
          <surface>
            <contact>
              <ode/>
            </contact>
            <friction>
              <ode/>
              <torsional>
                <ode/>
              </torsional>
            </friction>
            <bounce/>
          </surface>
          <max_contacts>10</max_contacts>
        </collision>
        <visual name='right_hand_middle_knuckle_link_visual'>
          <pose frame=''>0 0 0 0 -0 0</pose>
          <geometry>
            <mesh>
              <scale>0.001 0.001 0.001</scale>
              <uri>/home/centropiaggio/riccardo_ws/src/lab_library_ros/softhands/softhands_description/meshes/softhands/v2.0/right/qbh_prossimal_std_m_ng.stl</uri>
            </mesh>
          </geometry>
          <material>
            <script>
              <name>Gazebo/Grey</name>
              <uri>file://media/materials/scripts/gazebo.material</uri>
            </script>
          </material>
        </visual>
        <gravity>1</gravity>
        <velocity_decay/>
        <self_collide>1</self_collide>
        <enable_wind>0</enable_wind>
        <kinematic>0</kinematic>
      </link>
      <joint name='right_hand_middle_knuckle_joint' type='revolute'>
        <child>right_hand_middle_knuckle_link</child>
        <parent>right_hand_palm_base</parent>
        <axis>
          <xyz>1 -3e-06 0.000796</xyz>
          <limit>
            <lower>-0.785398</lower>
            <upper>1.57</upper>
            <effort>30</effort>
            <velocity>1</velocity>
          </limit>
          <dynamics>
            <damping>0.02</damping>
            <friction>0</friction>
            <spring_reference>0</spring_reference>
            <spring_stiffness>0</spring_stiffness>
          </dynamics>
          <use_parent_model_frame>1</use_parent_model_frame>
        </axis>
      </joint>
      <link name='right_hand_middle_proximal_link'>
        <pose frame=''>0.007561 0.0075 0.125106 1.5708 -1.57 3.14159</pose>
        <inertial>
          <pose frame=''>0.011574 0 0 0 -0 0</pose>
          <mass>0.005</mass>
          <inertia>
            <ixx>0.001</ixx>
            <ixy>0</ixy>
            <ixz>0</ixz>
            <iyy>0.001</iyy>
            <iyz>0</iyz>
            <izz>0.001</izz>
          </inertia>
        </inertial>
        <collision name='right_hand_middle_proximal_link_collision'>
          <pose frame=''>0.0065 0 0 0 -0 0</pose>
          <geometry>
            <mesh>
              <scale>0.001 0.001 0.001</scale>
              <uri>/home/centropiaggio/riccardo_ws/src/lab_library_ros/softhands/softhands_description/meshes/softhands/v2.0/right/phalanx_std_ng.stl</uri>
            </mesh>
          </geometry>
          <surface>
            <contact>
              <ode/>
            </contact>
            <friction>
              <ode/>
              <torsional>
                <ode/>
              </torsional>
            </friction>
            <bounce/>
          </surface>
          <max_contacts>10</max_contacts>
        </collision>
        <visual name='right_hand_middle_proximal_link_visual'>
          <pose frame=''>0.0065 0 0 0 -0 0</pose>
          <geometry>
            <mesh>
              <scale>0.001 0.001 0.001</scale>
              <uri>/home/centropiaggio/riccardo_ws/src/lab_library_ros/softhands/softhands_description/meshes/softhands/v2.0/right/phalanx_std_ng.stl</uri>
            </mesh>
          </geometry>
          <material>
            <script>
              <name>Gazebo/Grey</name>
              <uri>file://media/materials/scripts/gazebo.material</uri>
            </script>
          </material>
        </visual>
        <gravity>1</gravity>
        <velocity_decay/>
        <self_collide>1</self_collide>
        <enable_wind>0</enable_wind>
        <kinematic>0</kinematic>
      </link>
      <joint name='right_hand_middle_proximal_joint' type='revolute'>
        <child>right_hand_middle_proximal_link</child>
        <parent>right_hand_middle_knuckle_link</parent>
        <axis>
          <xyz>3e-06 1 0</xyz>
          <limit>
            <lower>-0.785398</lower>
            <upper>1.57</upper>
            <effort>30</effort>
            <velocity>1</velocity>
          </limit>
          <dynamics>
            <damping>0.02</damping>
            <friction>0</friction>
            <spring_reference>0</spring_reference>
            <spring_stiffness>0</spring_stiffness>
          </dynamics>
          <use_parent_model_frame>1</use_parent_model_frame>
        </axis>
      </joint>
      <link name='right_hand_middle_middle_link'>
        <pose frame=''>0.007543 0.0075 0.147106 1.5708 -1.57 3.14159</pose>
        <inertial>
          <pose frame=''>0.011574 0 0 0 -0 0</pose>
          <mass>0.005</mass>
          <inertia>
            <ixx>0.001</ixx>
            <ixy>0</ixy>
            <ixz>0</ixz>
            <iyy>0.001</iyy>
            <iyz>0</iyz>
            <izz>0.001</izz>
          </inertia>
        </inertial>
        <collision name='right_hand_middle_middle_link_collision'>
          <pose frame=''>0.0065 0 0 0 -0 0</pose>
          <geometry>
            <mesh>
              <scale>0.001 0.001 0.001</scale>
              <uri>/home/centropiaggio/riccardo_ws/src/lab_library_ros/softhands/softhands_description/meshes/softhands/v2.0/right/phalanx_std_ng.stl</uri>
            </mesh>
          </geometry>
          <surface>
            <contact>
              <ode/>
            </contact>
            <friction>
              <ode/>
              <torsional>
                <ode/>
              </torsional>
            </friction>
            <bounce/>
          </surface>
          <max_contacts>10</max_contacts>
        </collision>
        <visual name='right_hand_middle_middle_link_visual'>
          <pose frame=''>0.0065 0 0 0 -0 0</pose>
          <geometry>
            <mesh>
              <scale>0.001 0.001 0.001</scale>
              <uri>/home/centropiaggio/riccardo_ws/src/lab_library_ros/softhands/softhands_description/meshes/softhands/v2.0/right/phalanx_std_ng.stl</uri>
            </mesh>
          </geometry>
          <material>
            <script>
              <name>Gazebo/Grey</name>
              <uri>file://media/materials/scripts/gazebo.material</uri>
            </script>
          </material>
        </visual>
        <gravity>1</gravity>
        <velocity_decay/>
        <self_collide>1</self_collide>
        <enable_wind>0</enable_wind>
        <kinematic>0</kinematic>
      </link>
      <joint name='right_hand_middle_middle_joint' type='revolute'>
        <child>right_hand_middle_middle_link</child>
        <parent>right_hand_middle_proximal_link</parent>
        <axis>
          <xyz>3e-06 1 0</xyz>
          <limit>
            <lower>-0.785398</lower>
            <upper>1.57</upper>
            <effort>30</effort>
            <velocity>1</velocity>
          </limit>
          <dynamics>
            <damping>0.02</damping>
            <friction>0</friction>
            <spring_reference>0</spring_reference>
            <spring_stiffness>0</spring_stiffness>
          </dynamics>
          <use_parent_model_frame>1</use_parent_model_frame>
        </axis>
      </joint>
      <link name='right_hand_middle_distal_link'>
        <pose frame=''>0.007526 0.0075 0.169106 1.5708 -1.57 3.14159</pose>
        <inertial>
          <pose frame=''>0.011574 0 0 0 -0 0</pose>
          <mass>0.005</mass>
          <inertia>
            <ixx>0.001</ixx>
            <ixy>0</ixy>
            <ixz>0</ixz>
            <iyy>0.001</iyy>
            <iyz>0</iyz>
            <izz>0.001</izz>
          </inertia>
        </inertial>
        <collision name='right_hand_middle_distal_link_collision'>
          <pose frame=''>0.0065 0 0 0 -0 0</pose>
          <geometry>
            <mesh>
              <scale>0.001 0.001 0.001</scale>
              <uri>/home/centropiaggio/riccardo_ws/src/lab_library_ros/softhands/softhands_description/meshes/softhands/v2.0/right/qb_distal_ng.stl</uri>
            </mesh>
          </geometry>
          <surface>
            <contact>
              <ode/>
            </contact>
            <friction>
              <ode/>
              <torsional>
                <ode/>
              </torsional>
            </friction>
            <bounce/>
          </surface>
          <max_contacts>10</max_contacts>
        </collision>
        <visual name='right_hand_middle_distal_link_visual'>
          <pose frame=''>0.0065 0 0 0 -0 0</pose>
          <geometry>
            <mesh>
              <scale>0.001 0.001 0.001</scale>
              <uri>/home/centropiaggio/riccardo_ws/src/lab_library_ros/softhands/softhands_description/meshes/softhands/v2.0/right/qb_distal_ng.stl</uri>
            </mesh>
          </geometry>
          <material>
            <script>
              <name>Gazebo/Grey</name>
              <uri>file://media/materials/scripts/gazebo.material</uri>
            </script>
          </material>
        </visual>
        <gravity>1</gravity>
        <velocity_decay/>
        <self_collide>1</self_collide>
        <enable_wind>0</enable_wind>
        <kinematic>0</kinematic>
      </link>
      <joint name='right_hand_middle_distal_joint' type='revolute'>
        <child>right_hand_middle_distal_link</child>
        <parent>right_hand_middle_middle_link</parent>
        <axis>
          <xyz>3e-06 1 0</xyz>
          <limit>
            <lower>-0.785398</lower>
            <upper>1.57</upper>
            <effort>30</effort>
            <velocity>1</velocity>
          </limit>
          <dynamics>
            <damping>0.02</damping>
            <friction>0</friction>
            <spring_reference>0</spring_reference>
            <spring_stiffness>0</spring_stiffness>
          </dynamics>
          <use_parent_model_frame>1</use_parent_model_frame>
        </axis>
      </joint>
      <link name='right_hand_ring_knuckle_link'>
        <pose frame=''>0.007582 -0.0105 0.099006 -1.56166 -1.48353 -1.5799</pose>
        <inertial>
          <pose frame=''>0.001286 0 0.000425 0 -0 0</pose>
          <mass>0.009</mass>
          <inertia>
            <ixx>0.001</ixx>
            <ixy>0</ixy>
            <ixz>0</ixz>
            <iyy>0.001</iyy>
            <iyz>0</iyz>
            <izz>0.001</izz>
          </inertia>
        </inertial>
        <collision name='right_hand_ring_knuckle_link_collision'>
          <pose frame=''>0 0 0 0 -0 0</pose>
          <geometry>
            <mesh>
              <scale>0.001 0.001 0.001</scale>
              <uri>/home/centropiaggio/riccardo_ws/src/lab_library_ros/softhands/softhands_description/meshes/softhands/v2.0/right/qbh_prossimal_std_l_ng.stl</uri>
            </mesh>
          </geometry>
          <surface>
            <contact>
              <ode/>
            </contact>
            <friction>
              <ode/>
              <torsional>
                <ode/>
              </torsional>
            </friction>
            <bounce/>
          </surface>
          <max_contacts>10</max_contacts>
        </collision>
        <visual name='right_hand_ring_knuckle_link_visual'>
          <pose frame=''>0 0 0 0 -0 0</pose>
          <geometry>
            <mesh>
              <scale>0.001 0.001 0.001</scale>
              <uri>/home/centropiaggio/riccardo_ws/src/lab_library_ros/softhands/softhands_description/meshes/softhands/v2.0/right/qbh_prossimal_std_l_ng.stl</uri>
            </mesh>
          </geometry>
          <material>
            <script>
              <name>Gazebo/Grey</name>
              <uri>file://media/materials/scripts/gazebo.material</uri>
            </script>
          </material>
        </visual>
        <gravity>1</gravity>
        <velocity_decay/>
        <self_collide>1</self_collide>
        <enable_wind>0</enable_wind>
        <kinematic>0</kinematic>
      </link>
      <joint name='right_hand_ring_knuckle_joint' type='revolute'>
        <child>right_hand_ring_knuckle_link</child>
        <parent>right_hand_palm_base</parent>
        <axis>
          <xyz>1 -3e-06 0.000796</xyz>
          <limit>
            <lower>-0.785398</lower>
            <upper>1.57</upper>
            <effort>30</effort>
            <velocity>1</velocity>
          </limit>
          <dynamics>
            <damping>0.02</damping>
            <friction>0</friction>
            <spring_reference>0</spring_reference>
            <spring_stiffness>0</spring_stiffness>
          </dynamics>
          <use_parent_model_frame>1</use_parent_model_frame>
        </axis>
      </joint>
      <link name='right_hand_ring_proximal_link'>
        <pose frame=''>0.007565 -0.010048 0.120226 0.009137 -1.48353 -1.5799</pose>
        <inertial>
          <pose frame=''>0.011574 0 0 0 -0 0</pose>
          <mass>0.005</mass>
          <inertia>
            <ixx>0.001</ixx>
            <ixy>0</ixy>
            <ixz>0</ixz>
            <iyy>0.001</iyy>
            <iyz>0</iyz>
            <izz>0.001</izz>
          </inertia>
        </inertial>
        <collision name='right_hand_ring_proximal_link_collision'>
          <pose frame=''>0.0065 0 0 0 -0 0</pose>
          <geometry>
            <mesh>
              <scale>0.001 0.001 0.001</scale>
              <uri>/home/centropiaggio/riccardo_ws/src/lab_library_ros/softhands/softhands_description/meshes/softhands/v2.0/right/phalanx_std_ng.stl</uri>
            </mesh>
          </geometry>
          <surface>
            <contact>
              <ode/>
            </contact>
            <friction>
              <ode/>
              <torsional>
                <ode/>
              </torsional>
            </friction>
            <bounce/>
          </surface>
          <max_contacts>10</max_contacts>
        </collision>
        <visual name='right_hand_ring_proximal_link_visual'>
          <pose frame=''>0.0065 0 0 0 -0 0</pose>
          <geometry>
            <mesh>
              <scale>0.001 0.001 0.001</scale>
              <uri>/home/centropiaggio/riccardo_ws/src/lab_library_ros/softhands/softhands_description/meshes/softhands/v2.0/right/phalanx_std_ng.stl</uri>
            </mesh>
          </geometry>
          <material>
            <script>
              <name>Gazebo/Grey</name>
              <uri>file://media/materials/scripts/gazebo.material</uri>
            </script>
          </material>
        </visual>
        <gravity>1</gravity>
        <velocity_decay/>
        <self_collide>1</self_collide>
        <enable_wind>0</enable_wind>
        <kinematic>0</kinematic>
      </link>
      <joint name='right_hand_ring_proximal_joint' type='revolute'>
        <child>right_hand_ring_proximal_link</child>
        <parent>right_hand_ring_knuckle_link</parent>
        <axis>
          <xyz>-6.7e-05 0.996195 0.087156</xyz>
          <limit>
            <lower>-0.785398</lower>
            <upper>1.57</upper>
            <effort>30</effort>
            <velocity>1</velocity>
          </limit>
          <dynamics>
            <damping>0.02</damping>
            <friction>0</friction>
            <spring_reference>0</spring_reference>
            <spring_stiffness>0</spring_stiffness>
          </dynamics>
          <use_parent_model_frame>1</use_parent_model_frame>
        </axis>
      </joint>
      <link name='right_hand_ring_middle_link'>
        <pose frame=''>0.007547 -0.011965 0.142143 0.009137 -1.48353 -1.5799</pose>
        <inertial>
          <pose frame=''>0.011574 0 0 0 -0 0</pose>
          <mass>0.005</mass>
          <inertia>
            <ixx>0.001</ixx>
            <ixy>0</ixy>
            <ixz>0</ixz>
            <iyy>0.001</iyy>
            <iyz>0</iyz>
            <izz>0.001</izz>
          </inertia>
        </inertial>
        <collision name='right_hand_ring_middle_link_collision'>
          <pose frame=''>0.0065 0 0 0 -0 0</pose>
          <geometry>
            <mesh>
              <scale>0.001 0.001 0.001</scale>
              <uri>/home/centropiaggio/riccardo_ws/src/lab_library_ros/softhands/softhands_description/meshes/softhands/v2.0/right/phalanx_std_ng.stl</uri>
            </mesh>
          </geometry>
          <surface>
            <contact>
              <ode/>
            </contact>
            <friction>
              <ode/>
              <torsional>
                <ode/>
              </torsional>
            </friction>
            <bounce/>
          </surface>
          <max_contacts>10</max_contacts>
        </collision>
        <visual name='right_hand_ring_middle_link_visual'>
          <pose frame=''>0.0065 0 0 0 -0 0</pose>
          <geometry>
            <mesh>
              <scale>0.001 0.001 0.001</scale>
              <uri>/home/centropiaggio/riccardo_ws/src/lab_library_ros/softhands/softhands_description/meshes/softhands/v2.0/right/phalanx_std_ng.stl</uri>
            </mesh>
          </geometry>
          <material>
            <script>
              <name>Gazebo/Grey</name>
              <uri>file://media/materials/scripts/gazebo.material</uri>
            </script>
          </material>
        </visual>
        <gravity>1</gravity>
        <velocity_decay/>
        <self_collide>1</self_collide>
        <enable_wind>0</enable_wind>
        <kinematic>0</kinematic>
      </link>
      <joint name='right_hand_ring_middle_joint' type='revolute'>
        <child>right_hand_ring_middle_link</child>
        <parent>right_hand_ring_proximal_link</parent>
        <axis>
          <xyz>-6.7e-05 0.996195 0.087156</xyz>
          <limit>
            <lower>-0.785398</lower>
            <upper>1.57</upper>
            <effort>30</effort>
            <velocity>1</velocity>
          </limit>
          <dynamics>
            <damping>0.02</damping>
            <friction>0</friction>
            <spring_reference>0</spring_reference>
            <spring_stiffness>0</spring_stiffness>
          </dynamics>
          <use_parent_model_frame>1</use_parent_model_frame>
        </axis>
      </joint>
      <link name='right_hand_ring_distal_link'>
        <pose frame=''>0.00753 -0.013883 0.164059 0.009137 -1.48353 -1.5799</pose>
        <inertial>
          <pose frame=''>0.011574 0 0 0 -0 0</pose>
          <mass>0.005</mass>
          <inertia>
            <ixx>0.001</ixx>
            <ixy>0</ixy>
            <ixz>0</ixz>
            <iyy>0.001</iyy>
            <iyz>0</iyz>
            <izz>0.001</izz>
          </inertia>
        </inertial>
        <collision name='right_hand_ring_distal_link_collision'>
          <pose frame=''>0.0065 0 0 0 -0 0</pose>
          <geometry>
            <mesh>
              <scale>0.001 0.001 0.001</scale>
              <uri>/home/centropiaggio/riccardo_ws/src/lab_library_ros/softhands/softhands_description/meshes/softhands/v2.0/right/qb_distal_ng.stl</uri>
            </mesh>
          </geometry>
          <surface>
            <contact>
              <ode/>
            </contact>
            <friction>
              <ode/>
              <torsional>
                <ode/>
              </torsional>
            </friction>
            <bounce/>
          </surface>
          <max_contacts>10</max_contacts>
        </collision>
        <visual name='right_hand_ring_distal_link_visual'>
          <pose frame=''>0.0065 0 0 0 -0 0</pose>
          <geometry>
            <mesh>
              <scale>0.001 0.001 0.001</scale>
              <uri>/home/centropiaggio/riccardo_ws/src/lab_library_ros/softhands/softhands_description/meshes/softhands/v2.0/right/qb_distal_ng.stl</uri>
            </mesh>
          </geometry>
          <material>
            <script>
              <name>Gazebo/Grey</name>
              <uri>file://media/materials/scripts/gazebo.material</uri>
            </script>
          </material>
        </visual>
        <gravity>1</gravity>
        <velocity_decay/>
        <self_collide>1</self_collide>
        <enable_wind>0</enable_wind>
        <kinematic>0</kinematic>
      </link>
      <joint name='right_hand_ring_distal_joint' type='revolute'>
        <child>right_hand_ring_distal_link</child>
        <parent>right_hand_ring_middle_link</parent>
        <axis>
          <xyz>-6.7e-05 0.996195 0.087156</xyz>
          <limit>
            <lower>-0.785398</lower>
            <upper>1.57</upper>
            <effort>30</effort>
            <velocity>1</velocity>
          </limit>
          <dynamics>
            <damping>0.02</damping>
            <friction>0</friction>
            <spring_reference>0</spring_reference>
            <spring_stiffness>0</spring_stiffness>
          </dynamics>
          <use_parent_model_frame>1</use_parent_model_frame>
        </axis>
      </joint>
      <link name='right_hand_thumb_knuckle_link'>
        <pose frame=''>0.020947 0.04371 0.066447 -0.000919 -0.523599 1.57125</pose>
        <inertial>
          <pose frame=''>0 0 0 0 -0 0</pose>
          <mass>0.009</mass>
          <inertia>
            <ixx>0.001</ixx>
            <ixy>0</ixy>
            <ixz>0</ixz>
            <iyy>0.001</iyy>
            <iyz>0</iyz>
            <izz>0.001</izz>
          </inertia>
        </inertial>
        <collision name='right_hand_thumb_knuckle_link_collision'>
          <pose frame=''>0 0 0 0 -0 0</pose>
          <geometry>
            <mesh>
              <scale>0.001 0.001 0.001</scale>
              <uri>/home/centropiaggio/riccardo_ws/src/lab_library_ros/softhands/softhands_description/meshes/softhands/v2.0/right/qbh_prox_thumb_ng.stl</uri>
            </mesh>
          </geometry>
          <surface>
            <contact>
              <ode/>
            </contact>
            <friction>
              <ode/>
              <torsional>
                <ode/>
              </torsional>
            </friction>
            <bounce/>
          </surface>
          <max_contacts>10</max_contacts>
        </collision>
        <visual name='right_hand_thumb_knuckle_link_visual'>
          <pose frame=''>0 0 0 0 -0 0</pose>
          <geometry>
            <mesh>
              <scale>0.001 0.001 0.001</scale>
              <uri>/home/centropiaggio/riccardo_ws/src/lab_library_ros/softhands/softhands_description/meshes/softhands/v2.0/right/qbh_prox_thumb_ng.stl</uri>
            </mesh>
          </geometry>
          <material>
            <script>
              <name>Gazebo/Grey</name>
              <uri>file://media/materials/scripts/gazebo.material</uri>
            </script>
          </material>
        </visual>
        <gravity>1</gravity>
        <velocity_decay/>
        <self_collide>1</self_collide>
        <enable_wind>0</enable_wind>
        <kinematic>0</kinematic>
      </link>
      <joint name='right_hand_thumb_knuckle_joint' type='revolute'>
        <child>right_hand_thumb_knuckle_link</child>
        <parent>right_hand_palm_base</parent>
        <axis>
          <xyz>0.000691 0.5 -0.866025</xyz>
          <limit>
            <lower>-0.785398</lower>
            <upper>0.785398</upper>
            <effort>30</effort>
            <velocity>1</velocity>
          </limit>
          <dynamics>
            <spring_reference>0</spring_reference>
            <spring_stiffness>0</spring_stiffness>
          </dynamics>
          <use_parent_model_frame>1</use_parent_model_frame>
        </axis>
      </joint>
      <link name='right_hand_thumb_proximal_link'>
        <pose frame=''>0.024366 0.0621 0.081596 1.65714 -0.523599 1.57125</pose>
        <inertial>
          <pose frame=''>0.011574 0 0 0 -0 0</pose>
          <mass>0.05</mass>
          <inertia>
            <ixx>0.001</ixx>
            <ixy>0</ixy>
            <ixz>0</ixz>
            <iyy>0.001</iyy>
            <iyz>0</iyz>
            <izz>0.001</izz>
          </inertia>
        </inertial>
        <collision name='right_hand_thumb_proximal_link_collision'>
          <pose frame=''>0.0065 0 0 0 -0 0</pose>
          <geometry>
            <mesh>
              <scale>0.001 0.001 0.001</scale>
              <uri>/home/centropiaggio/riccardo_ws/src/lab_library_ros/softhands/softhands_description/meshes/softhands/v2.0/right/phalanx_std_ng.stl</uri>
            </mesh>
          </geometry>
          <surface>
            <contact>
              <ode/>
            </contact>
            <friction>
              <ode/>
              <torsional>
                <ode/>
              </torsional>
            </friction>
            <bounce/>
          </surface>
          <max_contacts>10</max_contacts>
        </collision>
        <visual name='right_hand_thumb_proximal_link_visual'>
          <pose frame=''>0.0065 0 0 0 -0 0</pose>
          <geometry>
            <mesh>
              <scale>0.001 0.001 0.001</scale>
              <uri>/home/centropiaggio/riccardo_ws/src/lab_library_ros/softhands/softhands_description/meshes/softhands/v2.0/right/phalanx_std_ng.stl</uri>
            </mesh>
          </geometry>
          <material>
            <script>
              <name>Gazebo/Grey</name>
              <uri>file://media/materials/scripts/gazebo.material</uri>
            </script>
          </material>
        </visual>
        <gravity>1</gravity>
        <velocity_decay/>
        <self_collide>1</self_collide>
        <enable_wind>0</enable_wind>
        <kinematic>0</kinematic>
      </link>
      <joint name='right_hand_thumb_proximal_joint' type='revolute'>
        <child>right_hand_thumb_proximal_link</child>
        <parent>right_hand_thumb_knuckle_link</parent>
        <axis>
          <xyz>0.996255 0.043576 -0.074686</xyz>
          <limit>
            <lower>-0.785398</lower>
            <upper>0.785398</upper>
            <effort>30</effort>
            <velocity>1</velocity>
          </limit>
          <dynamics>
            <spring_reference>0</spring_reference>
            <spring_stiffness>0</spring_stiffness>
          </dynamics>
          <use_parent_model_frame>1</use_parent_model_frame>
        </axis>
      </joint>
      <link name='right_hand_thumb_distal_link'>
        <pose frame=''>0.024357 0.081153 0.092596 1.65714 -0.523599 1.57125</pose>
        <inertial>
          <pose frame=''>0.011574 0 0 0 -0 0</pose>
          <mass>0.05</mass>
          <inertia>
            <ixx>0.001</ixx>
            <ixy>0</ixy>
            <ixz>0</ixz>
            <iyy>0.001</iyy>
            <iyz>0</iyz>
            <izz>0.001</izz>
          </inertia>
        </inertial>
        <collision name='right_hand_thumb_distal_link_collision'>
          <pose frame=''>0.0065 0 0 0 -0 0</pose>
          <geometry>
            <mesh>
              <scale>0.001 0.001 0.001</scale>
              <uri>/home/centropiaggio/riccardo_ws/src/lab_library_ros/softhands/softhands_description/meshes/softhands/v2.0/right/qb_distal_ng.stl</uri>
            </mesh>
          </geometry>
          <surface>
            <contact>
              <ode/>
            </contact>
            <friction>
              <ode/>
              <torsional>
                <ode/>
              </torsional>
            </friction>
            <bounce/>
          </surface>
          <max_contacts>10</max_contacts>
        </collision>
        <visual name='right_hand_thumb_distal_link_visual'>
          <pose frame=''>0.0065 0 0 0 -0 0</pose>
          <geometry>
            <mesh>
              <scale>0.001 0.001 0.001</scale>
              <uri>/home/centropiaggio/riccardo_ws/src/lab_library_ros/softhands/softhands_description/meshes/softhands/v2.0/right/qb_distal_ng.stl</uri>
            </mesh>
          </geometry>
          <material>
            <script>
              <name>Gazebo/Grey</name>
              <uri>file://media/materials/scripts/gazebo.material</uri>
            </script>
          </material>
        </visual>
        <gravity>1</gravity>
        <velocity_decay/>
        <self_collide>1</self_collide>
        <enable_wind>0</enable_wind>
        <kinematic>0</kinematic>
      </link>
      <joint name='right_hand_thumb_distal_joint' type='revolute'>
        <child>right_hand_thumb_distal_link</child>
        <parent>right_hand_thumb_proximal_link</parent>
        <axis>
          <xyz>0.996255 0.043576 -0.074686</xyz>
          <limit>
            <lower>-0.785398</lower>
            <upper>0.785398</upper>
            <effort>30</effort>
            <velocity>1</velocity>
          </limit>
          <dynamics>
            <spring_reference>0</spring_reference>
            <spring_stiffness>0</spring_stiffness>
          </dynamics>
          <use_parent_model_frame>1</use_parent_model_frame>
        </axis>
      </joint>
      <static>0</static>
      <plugin name='synergy_plugin' filename='libsofthand_plugin.so'>
        <namespace>right_hand</namespace>
        <operation_mode>0</operation_mode>
        <spring_k>20</spring_k>
        <spring_k_mimic>20</spring_k_mimic>
        <robotNamespace>/</robotNamespace>
      </plugin>
      <pose frame=''>0 0 0 0 -0 0</pose>
    </model>
    <state world_name='default'>
      <sim_time>0 0</sim_time>
      <real_time>0 0</real_time>
      <wall_time>1624013264 542979313</wall_time>
      <iterations>0</iterations>
      <model name='ground_plane'>
        <pose frame=''>0 0 0 0 -0 0</pose>
        <scale>1 1 1</scale>
        <link name='link'>
          <pose frame=''>0 0 0 0 -0 0</pose>
          <velocity>0 0 0 0 -0 0</velocity>
          <acceleration>0 0 0 0 -0 0</acceleration>
          <wrench>0 0 0 0 -0 0</wrench>
        </link>
      </model>
      <model name='softhands_description'>
        <pose frame=''>0 0 0 0 -0 0</pose>
        <scale>1 1 1</scale>
        <link name='object'>
          <pose frame=''>0.04 0.03 0.11 0 -0 0</pose>
          <velocity>0 0 0 0 -0 0</velocity>
          <acceleration>0 0 0 0 -0 0</acceleration>
          <wrench>0 0 0 0 -0 0</wrench>
        </link>
        <link name='right_hand_index_distal_link'>
          <pose frame=''>0.00753 0.034539 0.163516 3.13701 -1.39626 1.57531</pose>
          <velocity>0 0 0 0 -0 0</velocity>
          <acceleration>0 0 0 0 -0 0</acceleration>
          <wrench>0 0 0 0 -0 0</wrench>
        </link>
        <link name='right_hand_index_knuckle_link'>
          <pose frame=''>0.007582 0.0255 0.099006 1.56621 -1.39626 1.57531</pose>
          <velocity>0 0 0 0 -0 0</velocity>
          <acceleration>0 0 0 0 -0 0</acceleration>
          <wrench>0 0 0 0 -0 0</wrench>
        </link>
        <link name='right_hand_index_middle_link'>
          <pose frame=''>0.007548 0.030719 0.141851 3.13701 -1.39626 1.57531</pose>
          <velocity>0 0 0 0 -0 0</velocity>
          <acceleration>0 0 0 0 -0 0</acceleration>
          <wrench>0 0 0 0 -0 0</wrench>
        </link>
        <link name='right_hand_index_proximal_link'>
          <pose frame=''>0.007565 0.026899 0.120185 3.13701 -1.39626 1.57531</pose>
          <velocity>0 0 0 0 -0 0</velocity>
          <acceleration>0 0 0 0 -0 0</acceleration>
          <wrench>0 0 0 0 -0 0</wrench>
        </link>
        <link name='right_hand_little_distal_link'>
          <pose frame=''>0.007535 -0.040328 0.157483 0.003077 -1.309 -1.57377</pose>
          <velocity>0 0 0 0 -0 0</velocity>
          <acceleration>0 0 0 0 -0 0</acceleration>
          <wrench>0 0 0 0 -0 0</wrench>
        </link>
        <link name='right_hand_little_knuckle_link'>
          <pose frame=''>0.007586 -0.0257 0.094006 -1.56772 -1.309 -1.57377</pose>
          <velocity>0 0 0 0 -0 0</velocity>
          <acceleration>0 0 0 0 -0 0</acceleration>
          <wrench>0 0 0 0 -0 0</wrench>
        </link>
        <link name='right_hand_little_middle_link'>
          <pose frame=''>0.007552 -0.034634 0.136233 0.003077 -1.309 -1.57377</pose>
          <velocity>0 0 0 0 -0 0</velocity>
          <acceleration>0 0 0 0 -0 0</acceleration>
          <wrench>0 0 0 0 -0 0</wrench>
        </link>
        <link name='right_hand_little_proximal_link'>
          <pose frame=''>0.007569 -0.02894 0.114982 0.003077 -1.309 -1.57377</pose>
          <velocity>0 0 0 0 -0 0</velocity>
          <acceleration>0 0 0 0 -0 0</acceleration>
          <wrench>0 0 0 0 -0 0</wrench>
        </link>
        <link name='right_hand_middle_distal_link'>
          <pose frame=''>0.007526 0.0075 0.169106 1.5708 -1.57 3.14159</pose>
          <velocity>0 0 0 0 -0 0</velocity>
          <acceleration>0 0 0 0 -0 0</acceleration>
          <wrench>0 0 0 0 -0 0</wrench>
        </link>
        <link name='right_hand_middle_knuckle_link'>
          <pose frame=''>0.007578 0.0075 0.104006 0 -1.57 3.14159</pose>
          <velocity>0 0 0 0 -0 0</velocity>
          <acceleration>0 0 0 0 -0 0</acceleration>
          <wrench>0 0 0 0 -0 0</wrench>
        </link>
        <link name='right_hand_middle_middle_link'>
          <pose frame=''>0.007543 0.0075 0.147106 1.5708 -1.57 3.14159</pose>
          <velocity>0 0 0 0 -0 0</velocity>
          <acceleration>0 0 0 0 -0 0</acceleration>
          <wrench>0 0 0 0 -0 0</wrench>
        </link>
        <link name='right_hand_middle_proximal_link'>
          <pose frame=''>0.007561 0.0075 0.125106 1.5708 -1.57 3.14159</pose>
          <velocity>0 0 0 0 -0 0</velocity>
          <acceleration>0 0 0 0 -0 0</acceleration>
          <wrench>0 0 0 0 -0 0</wrench>
        </link>
        <link name='right_hand_palm_base'>
          <pose frame=''>0 0 0 0 -0 0</pose>
          <velocity>0 0 0 0 -0 0</velocity>
          <acceleration>0 0 0 0 -0 0</acceleration>
          <wrench>0 0 0 0 -0 0</wrench>
        </link>
        <link name='right_hand_ring_distal_link'>
          <pose frame=''>0.00753 -0.013883 0.164059 0.009137 -1.48353 -1.5799</pose>
          <velocity>0 0 0 0 -0 0</velocity>
          <acceleration>0 0 0 0 -0 0</acceleration>
          <wrench>0 0 0 0 -0 0</wrench>
        </link>
        <link name='right_hand_ring_knuckle_link'>
          <pose frame=''>0.007582 -0.0105 0.099006 -1.56166 -1.48353 -1.5799</pose>
          <velocity>0 0 0 0 -0 0</velocity>
          <acceleration>0 0 0 0 -0 0</acceleration>
          <wrench>0 0 0 0 -0 0</wrench>
        </link>
        <link name='right_hand_ring_middle_link'>
          <pose frame=''>0.007547 -0.011965 0.142143 0.009137 -1.48353 -1.5799</pose>
          <velocity>0 0 0 0 -0 0</velocity>
          <acceleration>0 0 0 0 -0 0</acceleration>
          <wrench>0 0 0 0 -0 0</wrench>
        </link>
        <link name='right_hand_ring_proximal_link'>
          <pose frame=''>0.007565 -0.010048 0.120226 0.009137 -1.48353 -1.5799</pose>
          <velocity>0 0 0 0 -0 0</velocity>
          <acceleration>0 0 0 0 -0 0</acceleration>
          <wrench>0 0 0 0 -0 0</wrench>
        </link>
        <link name='right_hand_thumb_distal_link'>
          <pose frame=''>0.024357 0.081153 0.092596 1.65714 -0.523599 1.57125</pose>
          <velocity>0 0 0 0 -0 0</velocity>
          <acceleration>0 0 0 0 -0 0</acceleration>
          <wrench>0 0 0 0 -0 0</wrench>
        </link>
        <link name='right_hand_thumb_knuckle_link'>
          <pose frame=''>0.020947 0.04371 0.066447 -0.000919 -0.523599 1.57125</pose>
          <velocity>0 0 0 0 -0 0</velocity>
          <acceleration>0 0 0 0 -0 0</acceleration>
          <wrench>0 0 0 0 -0 0</wrench>
        </link>
        <link name='right_hand_thumb_proximal_link'>
          <pose frame=''>0.024366 0.0621 0.081596 1.65714 -0.523599 1.57125</pose>
          <velocity>0 0 0 0 -0 0</velocity>
          <acceleration>0 0 0 0 -0 0</acceleration>
          <wrench>0 0 0 0 -0 0</wrench>
        </link>
      </model>
      <light name='sun'>
        <pose frame=''>0 0 10 0 -0 0</pose>
      </light>
    </state>
    <gui fullscreen='0'>
      <camera name='user_camera'>
        <pose frame=''>0.328343 -0.268738 0.206171 0 0.275643 2.35619</pose>
        <view_controller>orbit</view_controller>
        <projection_type>perspective</projection_type>
      </camera>
    </gui>
  </world>
</sdf>
