<?xml version="1.0"?>
<robot xmlns:xacro="http://www.ros.org/wiki/xacro">
  
  <xacro:macro name="thumb_v2_simple" params="type ns sign position orientation translation damping">

    <!-- KNUCKLE -->
    <joint name="${ns}_${type}_knuckle_joint" type="revolute">
      <origin xyz="${position}" rpy="${orientation}"/>
      <parent link="${ns}_palm_link"/>
      <child link="${ns}_${type}_knuckle_link"/>
      <axis xyz="0 0 ${sign}" />
      <limit effort="30" velocity="1.0" lower="0" upper="1.57" />
      <dynamics damping="${damping}" friction="0.0" />
    </joint>
    
    <link name="${ns}_${type}_knuckle_link">
      <inertial>
        <origin xyz="0 0 0"/>
        <mass value="0.009"/>
        <inertia ixx="0.001" ixy="0" ixz="0" iyy="0.001" iyz="0" izz="0.001"/>
      </inertial>
      <visual>
	<geometry>
	  <xacro:if value="${ns == 'right_hand_v2s'}">
	    <mesh filename="package://softhands_description/meshes/softhands/v2.0/right/qbh_prox_thumb_ng.stl" scale="0.001 0.001 0.001"/> 
	  </xacro:if>
	  <xacro:if value="${ns == 'left_hand_v2s'}">
	    <mesh filename="package://softhands_description/meshes/softhands/v2.0/left/qbh_prox_thumb_ng.stl" scale="0.001 0.001 0.001"/> 
	  </xacro:if>
	</geometry>
	<material name="qbmove/default"/>
	<origin xyz="0 0 0" rpy="0 0 0"/>
      </visual>		
      <collision>
	<geometry>
	  <xacro:if value="${ns == 'right_hand_v2s'}">
	    <mesh filename="package://softhands_description/meshes/softhands/v2.0/right/qbh_prox_thumb_ng_collision.stl" scale="0.001 0.001 0.001"/>  
	  </xacro:if>
	  <xacro:if value="${ns == 'left_hand_v2s'}">
	    <mesh filename="package://softhands_description/meshes/softhands/v2.0/left/qbh_prox_thumb_ng.stl" scale="0.001 0.001 0.001"/> 
	  </xacro:if>
	</geometry>
	<origin xyz="0 0 0" rpy="0 0 0"/>
      </collision>	      
    </link>
    <gazebo reference="${ns}_${type}_knuckle_link">
      <material>Gazebo/Grey</material>
      <!-- <selfCollide>true</selfCollide> -->
      <kp value="1e4" />
      <kd value="1e2" />
      <surface>
       <friction>
        <ode>
         <mu>0.133</mu> 
         <mu2>0.133</mu2>
        </ode>
       </friction>
      </surface>
    </gazebo>
    
    <joint name="${ns}_${type}_proximal_joint" type="revolute">
      <origin xyz="0.0235 ${sign*0.00343074} ${0.00392231+translation} " rpy="${1.57-sign*0.0880634} -0.3 0"/> <!-- 1.6580634 --> <!-- added offset on orientation -->
      <parent link="${ns}_${type}_knuckle_link"/>
      <child link="${ns}_${type}_proximal_link"/>
      <axis xyz="0 0 1" />
      <limit effort="30" velocity="1.0" lower="-0.785398" upper="1.57" />
      <dynamics damping="${damping}" friction="0.0" />
    </joint>
    
    <link name="${ns}_${type}_proximal_link">
      <inertial>
        <origin xyz="0.011574337 -${translation} 0"/>
        <mass value="0.05"/>
        <inertia ixx="0.001" ixy="0" ixz="0" iyy="0.001" iyz="0" izz="0.001"/>
      </inertial>
      <visual>
	<geometry>
	  <mesh filename="package://softhands_description/meshes/softhands/v2.0/right/phalanx_std_ng.stl" scale="0.001 0.001 0.001"/> 
	</geometry>
	<material name="qbmove/default"/>
	<origin xyz="0.0065 -${translation} 0" rpy="0 0 0"/>
      </visual>		
      <collision>
        <geometry>
          <mesh filename="package://softhands_description/meshes/softhands/v2.0/right/phalanx_std_ng_collision.stl" scale="0.001 0.001 0.001"/> 
        </geometry>
        <origin xyz="0.0065 0 0" rpy="0 0 0"/>
      </collision>      
    </link>
    <gazebo reference="${ns}_${type}_proximal_link">
      <material>Gazebo/Grey</material>
      <!-- <selfCollide>true</selfCollide> -->
      <kp value="1e4" />
      <kd value="1e2" />
      <surface>
       <friction>
        <ode>
         <mu>0.133</mu> 
         <mu2>0.133</mu2>
        </ode>
       </friction>
      </surface>
    </gazebo>

    <joint name="${ns}_${type}_distal_joint" type="revolute">
      <origin xyz="0.022 0 0" rpy="0 0 0.3"/> <!-- added offset on orientation -->
      <parent link="${ns}_${type}_proximal_link"/>
      <child link="${ns}_${type}_distal_link"/>
      <limit effort="30" velocity="1.0" lower="-0.785398" upper="1.57" />
      <axis xyz="0 0 1" />
      <dynamics damping="${damping}" friction="0.0" />
    </joint>
    
    <link name="${ns}_${type}_distal_link">
      <inertial>
        <origin xyz="0.011574337 -${translation} 0"/>
        <mass value="0.05"/>
        <inertia ixx="0.001" ixy="0" ixz="0" iyy="0.001" iyz="0" izz="0.001"/>
      </inertial>
      <visual>
	<geometry>
	  <mesh filename="package://softhands_description/meshes/softhands/v2.0/right/qb_distal_ng.stl" scale="0.001 0.001 0.001"/> 
	</geometry>
	<material name="qbmove/default"/>
	<origin xyz="0.0065 -${translation} 0" rpy="0 0 0"/>
      </visual>		
      <collision>
        <geometry>
          <mesh filename="package://softhands_description/meshes/softhands/v2.0/right/qb_distal_ng_collision.stl" scale="0.001 0.001 0.001"/> 
        </geometry>
        <origin xyz="0.0065 -${translation} 0" rpy="0 0 0"/>
      </collision>        
    </link>
    <gazebo reference="${ns}_${type}_distal_link">
      <material>Gazebo/Grey</material>
      <selfCollide>true</selfCollide>
      <kp value="1e4" />
      <kd value="1e2" />
      <surface>
       <friction>
        <ode>
         <mu>0.133</mu> 
         <mu2>0.133</mu2>
        </ode>
       </friction>
      </surface>
    </gazebo>
    
    </xacro:macro>

</robot>
    