<?xml version="1.0"?>
<!-- 
 *  Software License Agreement: BSD 3-Clause License
 *
 * Copyright (c) 2021, NMMI
 * All rights reserved.
 *
 * Redistribution and use in source and binary forms, with or without
 * modification, are permitted provided that the following conditions are met:
 *
 * Redistributions of source code must retain the above copyright notice, this
 * list of conditions and the following disclaimer.
 *
 * Redistributions in binary form must reproduce the above copyright notice,
 * this list of conditions and the following disclaimer in the documentation
 * and/or other materials provided with the distribution.
 *
 * Neither the name of the copyright holder nor the names of its
 * contributors may be used to endorse or promote products derived from
 * this software without specific prior written permission.
 *
 * THIS SOFTWARE IS PROVIDED BY THE COPYRIGHT HOLDERS AND CONTRIBUTORS "AS IS"
 * AND ANY EXPRESS OR IMPLIED WARRANTIES, INCLUDING, BUT NOT LIMITED TO, THE
 * IMPLIED WARRANTIES OF MERCHANTABILITY AND FITNESS FOR A PARTICULAR PURPOSE ARE
 * DISCLAIMED. IN NO EVENT SHALL THE COPYRIGHT HOLDER OR CONTRIBUTORS BE LIABLE
 * FOR ANY DIRECT, INDIRECT, INCIDENTAL, SPECIAL, EXEMPLARY, OR CONSEQUENTIAL
 * DAMAGES (INCLUDING, BUT NOT LIMITED TO, PROCUREMENT OF SUBSTITUTE GOODS OR
 * SERVICES; LOSS OF USE, DATA, OR PROFITS; OR BUSINESS INTERRUPTION) HOWEVER
 * CAUSED AND ON ANY THEORY OF LIABILITY, WHETHER IN CONTRACT, STRICT LIABILITY,
 * OR TORT (INCLUDING NEGLIGENCE OR OTHERWISE) ARISING IN ANY WAY OUT OF THE USE
 * OF THIS SOFTWARE, EVEN IF ADVISED OF THE POSSIBILITY OF SUCH DAMAGE.
 *
 * \file      finger.xacro
 *
 * \author       _Centro di Ricerca "E.Piaggio"_
 * \author       _Istituto Italiano di Tecnologia, Soft Robotics for Human Cooperation and Rehabilitation Lab_
 *
-->

<robot xmlns:xacro="http://www.ros.org/wiki/xacro">

  <xacro:macro name="thumb_knuckle" params="type ns position orientation">


    <!-- KNUCKLE -->
    <joint name="${ns}_${type}_knuckle_joint" type="revolute">
      <origin xyz="${position}" rpy="${orientation}"/>
      <parent link="${ns}_palm_link"/>
      <child link="${ns}_${type}_knuckle_link"/>
      <limit effort="30" velocity="1.0" lower="-1.57" upper="1.57" />
      <axis xyz="0 0 ${sign*-1}" />
      <dynamics damping="0.08" friction="0.0" />
    </joint>
    <link name="${ns}_${type}_knuckle_link">
      <inertial>
        <origin xyz="0.001285644 0 0.000425011"/>
        <mass value="0.09"/>
        <inertia ixx="0.001" ixy="0" ixz="0" iyy="0.001" iyz="0" izz="0.001"/>
      </inertial>
      
      <visual>
        <geometry>
          <mesh filename="package://softhands_description/meshes/softhands/v1.0/${side}/thumb_knuckle_${side}_m.stl"/>
        </geometry>
      </visual>
      <collision>
        <geometry>
          <mesh filename="package://softhands_description/meshes/softhands/v1.0/${side}/thumb_knuckle_${side}_m.stl"/>
        </geometry>
      </collision>

    </link>

    <gazebo reference="${ns}_${type}_knuckle_link">
      <material>Gazebo/Grey</material>
      <selfCollide>true</selfCollide>
	  </gazebo>

  </xacro:macro>

</robot>