<?xml version="1.0"?>

<robot xmlns:xacro="http://www.ros.org/wiki/xacro">
   
    <xacro:macro name="phalanx_dist" params="name parent side *origin ns mass **inertia_origin *inertia">



		
		<!-- Virtual joint from middle->distal   -->

		<joint name="${ns}_${name}_virtual_joint" type="revolute">
			<axis xyz="0 0 1"/>
			<limit effort="30" velocity="0.0" lower="0" upper="0.785398" />
			<xacro:insert_block name="origin"/>
			<parent link="${ns}_${parent}_link"/>
			<child link="${ns}_${name}_virtual_link"/>
			<dynamics damping="$(arg virtual_damping)" friction="$(arg virtual_friction)"/>
		</joint>

		<link name="${ns}_${name}_virtual_link">
		   <inertial>
				<origin rpy="0 0 0" xyz="0 0 0"/>
					<mass value="${mass}"/>
					<xacro:insert_block name="inertia"/>
		   </inertial>
	
	    </link>

		<!-- Proximal phalanx -->

		<joint name="${ns}_${name}_joint" type="revolute">
			<axis xyz="0 0 1"/>
			<limit effort="30" velocity="0.0" lower="0" upper="0.785398" />
			<origin rpy="0 0 0" xyz="9e-3 0 0"/>
            <parent link="${ns}_${name}_virtual_link"/>
			<child link="${ns}_${name}_link"/>
			<dynamics damping="$(arg damping)" friction="$(arg friction)"/>
		</joint>

		<link name="${ns}_${name}_link">
				<visual>
				<material name="grey" />
					<geometry>
					<mesh
						filename="package://softhands_description/meshes/v1_wide/${side}/phalanx_dist.stl"
						scale="0.001 0.001 0.001" />
					</geometry>
				<origin xyz="0 0 0" rpy="0 0 0" />
				</visual>
				<inertial>
					<mass value="${mass}"/>
					<xacro:insert_block name="inertia"/>
					<xacro:insert_block name="inertia_origin"/>
				</inertial>
				<collision>
					<geometry>
					<mesh
						filename="package://softhands_description/meshes/v1_wide/${side}/phalanx_dist_collision.stl"
						scale="0.0009 0.0009 0.0009" />
					</geometry>
				<origin xyz="0 0 0" rpy="0 0 0" />
				</collision>
		</link>

		<gazebo reference="${ns}_${name}_link">
			<material>Gazebo/Gray</material>
			<selfCollide>$(arg selfCollide)</selfCollide>
		</gazebo>

						        <!-- GAZEBO REF -->
		<gazebo reference="${ns}_${name}_virtual_joint">
		<implicitSpringDamper>true</implicitSpringDamper>
				<springStiffness>0.4</springStiffness>
				<springReference>0</springReference>
		</gazebo>
						        <!-- GAZEBO REF -->
		<gazebo reference="${ns}_${name}_joint">
		<implicitSpringDamper>true</implicitSpringDamper>
				<springStiffness>0.4</springStiffness>
				<springReference>0</springReference>
		</gazebo>

    </xacro:macro>
</robot>