<?xml version="1.0"?>
<!-- 
 *  Software License Agreement: BSD 3-Clause License
 *
 * Copyright (c) 2021, NMMI
 * All rights reserved.
 *
 * Redistribution and use in source and binary forms, with or without
 * modification, are permitted provided that the following conditions are met:
 *
 * Redistributions of source code must retain the above copyright notice, this
 * list of conditions and the following disclaimer.
 *
 * Redistributions in binary form must reproduce the above copyright notice,
 * this list of conditions and the following disclaimer in the documentation
 * and/or other materials provided with the distribution.
 *
 * Neither the name of the copyright holder nor the names of its
 * contributors may be used to endorse or promote products derived from
 * this software without specific prior written permission.
 *
 * THIS SOFTWARE IS PROVIDED BY THE COPYRIGHT HOLDERS AND CONTRIBUTORS "AS IS"
 * AND ANY EXPRESS OR IMPLIED WARRANTIES, INCLUDING, BUT NOT LIMITED TO, THE
 * IMPLIED WARRANTIES OF MERCHANTABILITY AND FITNESS FOR A PARTICULAR PURPOSE ARE
 * DISCLAIMED. IN NO EVENT SHALL THE COPYRIGHT HOLDER OR CONTRIBUTORS BE LIABLE
 * FOR ANY DIRECT, INDIRECT, INCIDENTAL, SPECIAL, EXEMPLARY, OR CONSEQUENTIAL
 * DAMAGES (INCLUDING, BUT NOT LIMITED TO, PROCUREMENT OF SUBSTITUTE GOODS OR
 * SERVICES; LOSS OF USE, DATA, OR PROFITS; OR BUSINESS INTERRUPTION) HOWEVER
 * CAUSED AND ON ANY THEORY OF LIABILITY, WHETHER IN CONTRACT, STRICT LIABILITY,
 * OR TORT (INCLUDING NEGLIGENCE OR OTHERWISE) ARISING IN ANY WAY OUT OF THE USE
 * OF THIS SOFTWARE, EVEN IF ADVISED OF THE POSSIBILITY OF SUCH DAMAGE.
 *
 * \file      thumb.xacro
 *
 * \author       _Centro di Ricerca "E.Piaggio"_
 * \author       _Istituto Italiano di Tecnologia, Soft Robotics for Human Cooperation and Rehabilitation Lab_
 *
-->

<robot xmlns:xacro="http://www.ros.org/wiki/xacro">
  
  <xacro:macro name="thumb_v2" params="type ns sign position orientation">

    <!-- KNUCKLE -->
    <joint name="${ns}_${type}_knuckle_joint" type="revolute">
      <origin xyz="${position}" rpy="${orientation}"/>
      <parent link="${ns}_palm_link"/>
      <child link="${ns}_${type}_knuckle_link"/>
      <axis xyz="0 0 ${sign}" />
      <limit effort="30" velocity="1.0" lower="0" upper="1.57" />
      <dynamics damping="0.08" friction="0.0" />
    </joint>
    
    <link name="${ns}_${type}_knuckle_link">
      <inertial>
        <origin xyz="0 0 0"/>
        <mass value="0.009"/>
        <inertia ixx="0.001" ixy="0" ixz="0" iyy="0.001" iyz="0" izz="0.001"/>
      </inertial>
      <visual>
	<geometry>
	  <mesh filename="package://softhands_description/meshes/softhands/v2.0/right/qbh_prox_thumb_ng.stl" scale="0.001 0.001 0.001"/> 
	</geometry>
	<material name="qbmove/default"/>
	<origin xyz="0 0 0" rpy="0 0 0"/>
      </visual>		
      <collision>
	<geometry>
	  <mesh filename="package://softhands_description/meshes/softhands/v2.0/right/qbh_prox_thumb_ng_collision.stl" scale="0.001 0.001 0.001"/> 
	</geometry>
	<origin xyz="0 0 0" rpy="0 0 0"/>
      </collision>	      
    </link>
    <gazebo reference="${ns}_${type}_knuckle_link">
      <material>Gazebo/Grey</material>
      <kp value="1e4" />
      <kd value="1e2" />
      <surface>
       <friction>
        <ode>
         <mu>0.133</mu> 
         <mu2>0.133</mu2>
        </ode>
       </friction>
      </surface>
    </gazebo>
    
    <joint name="${ns}_${type}_proximal_joint" type="revolute">
      <origin xyz="0.017 -0.00343074 0.00392231" rpy="1.6580634 -0.15 0"/> <!-- added offset on orientation -->
      <parent link="${ns}_${type}_knuckle_link"/>
      <child link="${ns}_${type}_proximal_link_fake"/>
      <axis xyz="0 0 1" />
      <limit effort="30" velocity="10" lower="-0.785398" upper="1.57" />
      <dynamics damping="0.08" friction="0.0" />
    </joint>
    
    <link name="${ns}_${type}_proximal_link_fake">
      <inertial>
      	<origin xyz="0 0 0"/>
      	<mass value="0.001"/>
      	<inertia ixx="0.0001" ixy="0.0" ixz="0.0" iyy="0.0001" iyz="0.0" izz="0.0001" />
      </inertial>
      <visual>
        <geometry>
          <box size="0.001 0.001 0.001"/> 
        </geometry>
        <origin xyz="0 0 0" rpy="0 0 0"/>
      </visual>         
    </link>
    <gazebo reference="${ns}_${type}_proximal_link_fake">
      <material>Gazebo/Grey</material>
      <kp value="1e4" />
      <kd value="1e2" />
      <surface>
       <friction>
        <ode>
         <mu>0.133</mu> 
         <mu2>0.133</mu2>
        </ode>
       </friction>
      </surface>
    </gazebo>

    <joint name="${ns}_${type}_proximal_virtual_joint" type="revolute">
      <origin xyz="0.013 0 0" rpy="0 -0.15 0"/> <!-- added offset on orientation -->
      <parent link="${ns}_${type}_proximal_link_fake"/>
      <child link="${ns}_${type}_proximal_link"/>
      <axis xyz="0 0 1" />
      <limit effort="30" velocity="1.0" lower="-0.785398" upper="1.57" />
      <dynamics damping="0.08" friction="0.0" />
    </joint>
    
    <link name="${ns}_${type}_proximal_link">
      <inertial>
        <origin xyz="0.005074337 0 0"/>
        <mass value="0.05"/>
        <inertia ixx="0.001" ixy="0" ixz="0" iyy="0.001" iyz="0" izz="0.001"/>
      </inertial>
      <visual>
	<geometry>
	  <mesh filename="package://softhands_description/meshes/softhands/v2.0/right/phalanx_std_ng.stl" scale="0.001 0.001 0.001"/> 
	</geometry>
	<material name="qbmove/default"/>
	<origin xyz="0 0 0" rpy="0 0 0"/>
      </visual>		
      <collision>
        <geometry>
          <mesh filename="package://softhands_description/meshes/softhands/v2.0/right/phalanx_std_ng_collision.stl" scale="0.001 0.001 0.001"/> 
        </geometry>
        <origin xyz="0 0 0" rpy="0 0 0"/>
      </collision>      
    </link>
    <gazebo reference="${ns}_${type}_proximal_link">
      <material>Gazebo/Grey</material>
      <kp value="1e4" />
      <kd value="1e2" />
      <surface>
       <friction>
        <ode>
         <mu>0.133</mu> 
         <mu2>0.133</mu2>
        </ode>
       </friction>
      </surface>
    </gazebo>

    <joint name="${ns}_${type}_distal_joint" type="revolute">
      <origin xyz="0.009 0 0" rpy="0 0 0.15"/> <!-- added offset on orientation -->
      <parent link="${ns}_${type}_proximal_link"/>
      <child link="${ns}_${type}_distal_link_fake"/>
      <limit effort="30" velocity="1.0" lower="-0.785398" upper="1.57" />
      <dynamics damping="0.08" friction="0.0" />
      <axis xyz="0 0 1" />
    </joint>
    
    <link name="${ns}_${type}_distal_link_fake">
     <inertial>
	<origin xyz="0 0 0" rpy="0 0 0"/>
	<mass value="0.001"/>
	<inertia ixx="0.0001"  ixy="0"  	    ixz="0" 
				iyy="0.0001" 	    iyz="0" 
						    izz="0.0001" />
      </inertial>
      <visual>
        <geometry>
          <box size="0.001 0.001 0.001"/> 
        </geometry>
        <origin xyz="0 0 0" rpy="0 0 0"/>
      </visual> 
    </link>    
    <gazebo reference="${ns}_${type}_distal_link_fake">
      <material>Gazebo/Grey</material>
      <kp value="1e4" />
      <kd value="1e2" />
      <surface>
       <friction>
        <ode>
         <mu>0.133</mu> 
         <mu2>0.133</mu2>
        </ode>
       </friction>
      </surface>
    </gazebo>

    <joint name="${ns}_${type}_distal_virtual_joint" type="revolute">
      <origin xyz="0.013 0 0" rpy="0 0 0.15"/> <!-- added offset on orientation -->
      <parent link="${ns}_${type}_distal_link_fake"/>
      <child link="${ns}_${type}_distal_link"/>
      <limit effort="30" velocity="1.0" lower="-0.785398" upper="0.785398" />
      <dynamics damping="0.05" friction="0.0" />
      <axis xyz="0 0 1" />
    </joint>
    
    <link name="${ns}_${type}_distal_link">
      <inertial>
        <origin xyz="0.005074337 0 0"/>
        <mass value="0.05"/>
        <inertia ixx="0.001" ixy="0" ixz="0" iyy="0.001" iyz="0" izz="0.001"/>
      </inertial>
      <visual>
	<geometry>
	  <mesh filename="package://softhands_description/meshes/softhands/v2.0/right/qb_distal_ng.stl" scale="0.001 0.001 0.001"/> 
	</geometry>
	<material name="qbmove/default"/>
	<origin xyz="0 0 0" rpy="0 0 0"/>
      </visual>		
      <collision>
        <geometry>
          <mesh filename="package://softhands_description/meshes/softhands/v2.0/right/qb_distal_ng_collision.stl" scale="0.001 0.001 0.001"/> 
        </geometry>
        <origin xyz="0 0 0" rpy="0 0 0"/>
      </collision>        
    </link>
    <gazebo reference="${ns}_${type}_distal_link">
      <material>Gazebo/Grey</material>
      <selfCollide>true</selfCollide>
      <kp value="1e4" />
      <kd value="1e2" />
      <surface>
       <friction>
        <ode>
         <mu>0.133</mu> 
         <mu2>0.133</mu2>
        </ode>
       </friction>
      </surface>
    </gazebo>
    
    </xacro:macro>
</robot>
    